Workbook
Name Slicer_Department: #N/A

Sheet Employee_Data
A1: Employee_Name | B1: First_Name | C1: Last_name | D1: Tenure_Years | E1: Salary_Band | F1: Performance_Category | G1: Attrition_Type | H1: EmpID | I1: MarriedID | J1: MaritalStatusID | K1: GenderID | L1: EmpStatusID | M1: DeptID | N1: PerfScoreID | O1: FromDiversityJobFairID | P1: Salary | Q1: Termd | R1: PositionID | S1: Position | T1: State | U1: Zip | V1: DOB | W1: Sex | X1: MaritalDesc | Y1: CitizenDesc | Z1: HispanicLatino | AA1: RaceDesc | AB1: DateofHire | AC1: DateofTermination | AD1: TermReason | AE1: EmploymentStatus | AF1: Department | AG1: ManagerName | AH1: ManagerID | AI1: RecruitmentSource | AJ1: PerformanceScore | AK1: EngagementSurvey | AL1: EmpSatisfaction | AM1: SpecialProjectsCount | AN1: LastPerformanceReview_Date | AO1: DaysLateLast30 | AP1: Absences
A2: Adinolfi, Wilson K | B2: =TRIM(MID(A2, FIND(",", A2)+1, LEN(A2))) -> Wilson K | C2: =TRIM(LEFT(A2, FIND(",", A2)-1)) -> Adinolfi | D2: =IFERROR(DATEDIF(AB2, AC2, "Y"), DATEDIF(AB2, TODAY(), "Y")) -> 14 | E2: MID | F2: {=_xlfn.IFS(AJ2="Exceeds", "Top Performer", AJ2="Fully Meets", "Solid Performer", AJ2="Needs Improvement", "Underperformer", AJ2="PIP", "At Risk")} -> Top Performer | G2: {=_xlfn.IFS(AE2="Active", "Retained", AE2="Voluntarily Terminated", "Voluntary Exit", AE2="Terminated for Cause", "Involuntary Exit")} -> Retained | H2: 10026 | I2: 0 | J2: 0 | K2: 1 | L2: 1 | M2: 5 | N2: 4 | O2: 0 | P2: 62506 | Q2: 0 | R2: 19 | S2: Production Technician I | T2: MA | U2: 1960 | V2: 30507 | W2: M | X2: Single | Y2: US Citizen | Z2: No | AA2: White | AB2: 40729 | AD2: N/A-StillEmployed | AE2: Active | AF2: Production | AG2: Michael Albert | AH2: 22 | AI2: LinkedIn | AJ2: Exceeds | AK2: 4.6 | AL2: 5 | AM2: 0 | AN2: 43482 | AO2: 0 | AP2: 1
A3: Ait Sidi, Karthikeyan | B3: =TRIM(MID(A3, FIND(",", A3)+1, LEN(A3))) -> Karthikeyan | C3: =TRIM(LEFT(A3, FIND(",", A3)-1)) -> Ait Sidi | D3: =IFERROR(DATEDIF(AB3, AC3, "Y"), DATEDIF(AB3, TODAY(), "Y")) -> 1 | E3: {=_xlfn.IFS(P3<40000, "Low", P3<70000, "MID", P3<100000, "HIGH", P3>=100000, "Executive")} -> Executive | F3: {=_xlfn.IFS(AJ3="Exceeds", "Top Performer", AJ3="Fully Meets", "Solid Performer", AJ3="Needs Improvement", "Underperformer", AJ3="PIP", "At Risk")} -> Solid Performer | G3: {=_xlfn.IFS(AE3="Active", "Retained", AE3="Voluntarily Terminated", "Voluntary Exit", AE3="Terminated for Cause", "Involuntary Exit")} -> Voluntary Exit | H3: 10084 | I3: 1 | J3: 1 | K3: 1 | L3: 5 | M3: 3 | N3: 3 | O3: 0 | P3: 104437 | Q3: 1 | R3: 27 | S3: Sr. DBA | T3: MA | U3: 2148 | V3: 27519 | W3: M | X3: Married | Y3: US Citizen | Z3: No | AA3: White | AB3: 42093 | AC3: 42537 | AD3: career change | AE3: Voluntarily Terminated | AF3: IT/IS | AG3: Simon Roup | AH3: 4 | AI3: Indeed | AJ3: Fully Meets | AK3: 4.96 | AL3: 3 | AM3: 6 | AN3: 42424 | AO3: 0 | AP3: 17
A4: Akinkuolie, Sarah | B4: =TRIM(MID(A4, FIND(",", A4)+1, LEN(A4))) -> Sarah | C4: =TRIM(LEFT(A4, FIND(",", A4)-1)) -> Akinkuolie | D4: =IFERROR(DATEDIF(AB4, AC4, "Y"), DATEDIF(AB4, TODAY(), "Y")) -> 1 | E4: {=_xlfn.IFS(P4<40000, "Low", P4<70000, "MID", P4<100000, "HIGH", P4>=100000, "Executive")} -> MID | F4: {=_xlfn.IFS(AJ4="Exceeds", "Top Performer", AJ4="Fully Meets", "Solid Performer", AJ4="Needs Improvement", "Underperformer", AJ4="PIP", "At Risk")} -> Solid Performer | G4: {=_xlfn.IFS(AE4="Active", "Retained", AE4="Voluntarily Terminated", "Voluntary Exit", AE4="Terminated for Cause", "Involuntary Exit")} -> Voluntary Exit | H4: 10196 | I4: 1 | J4: 1 | K4: 0 | L4: 5 | M4: 5 | N4: 3 | O4: 0 | P4: 64955 | Q4: 1 | R4: 20 | S4: Production Technician II | T4: MA | U4: 1810 | V4: 32405 | W4: F | X4: Married | Y4: US Citizen | Z4: No | AA4: White | AB4: 40729 | AC4: 41176 | AD4: hours | AE4: Voluntarily Terminated | AF4: Production | AG4: Kissy Sullivan | AH4: 20 | AI4: LinkedIn | AJ4: Fully Meets | AK4: 3.02 | AL4: 3 | AM4: 0 | AN4: 41044 | AO4: 0 | AP4: 3
A5: Alagbe,Trina | B5: =TRIM(MID(A5, FIND(",", A5)+1, LEN(A5))) -> Trina | C5: =TRIM(LEFT(A5, FIND(",", A5)-1)) -> Alagbe | D5: =IFERROR(DATEDIF(AB5, AC5, "Y"), DATEDIF(AB5, TODAY(), "Y")) -> 18 | E5: {=_xlfn.IFS(P5<40000, "Low", P5<70000, "MID", P5<100000, "HIGH", P5>=100000, "Executive")} -> MID | F5: {=_xlfn.IFS(AJ5="Exceeds", "Top Performer", AJ5="Fully Meets", "Solid Performer", AJ5="Needs Improvement", "Underperformer", AJ5="PIP", "At Risk")} -> Solid Performer | G5: {=_xlfn.IFS(AE5="Active", "Retained", AE5="Voluntarily Terminated", "Voluntary Exit", AE5="Terminated for Cause", "Involuntary Exit")} -> Retained | H5: 10088 | I5: 1 | J5: 1 | K5: 0 | L5: 1 | M5: 5 | N5: 3 | O5: 0 | P5: 64991 | Q5: 0 | R5: 19 | S5: Production Technician I | T5: MA | U5: 1886 | V5: 32413 | W5: F | X5: Married | Y5: US Citizen | Z5: No | AA5: White | AB5: 39454 | AD5: N/A-StillEmployed | AE5: Active | AF5: Production | AG5: Elijiah Gray | AH5: 16 | AI5: Indeed | AJ5: Fully Meets | AK5: 4.84 | AL5: 5 | AM5: 0 | AN5: 43468 | AO5: 0 | AP5: 15
A6: Anderson, Carol | B6: =TRIM(MID(A6, FIND(",", A6)+1, LEN(A6))) -> Carol | C6: =TRIM(LEFT(A6, FIND(",", A6)-1)) -> Anderson | D6: =IFERROR(DATEDIF(AB6, AC6, "Y"), DATEDIF(AB6, TODAY(), "Y")) -> 5 | E6: {=_xlfn.IFS(P6<40000, "Low", P6<70000, "MID", P6<100000, "HIGH", P6>=100000, "Executive")} -> MID | F6: {=_xlfn.IFS(AJ6="Exceeds", "Top Performer", AJ6="Fully Meets", "Solid Performer", AJ6="Needs Improvement", "Underperformer", AJ6="PIP", "At Risk")} -> Solid Performer | G6: {=_xlfn.IFS(AE6="Active", "Retained", AE6="Voluntarily Terminated", "Voluntary Exit", AE6="Terminated for Cause", "Involuntary Exit")} -> Voluntary Exit | H6: 10069 | I6: 0 | J6: 2 | K6: 0 | L6: 5 | M6: 5 | N6: 3 | O6: 0 | P6: 50825 | Q6: 1 | R6: 19 | S6: Production Technician I | T6: MA | U6: 2169 | V6: 32759 | W6: F | X6: Divorced | Y6: US Citizen | Z6: No | AA6: White | AB6: 40735 | AC6: 42619 | AD6: return to school | AE6: Voluntarily Terminated | AF6: Production | AG6: Webster Butler | AH6: 39 | AI6: Google Search | AJ6: Fully Meets | AK6: 5 | AL6: 4 | AM6: 0 | AN6: 42401 | AO6: 0 | AP6: 2
A7: Anderson, Linda | B7: =TRIM(MID(A7, FIND(",", A7)+1, LEN(A7))) -> Linda | C7: =TRIM(LEFT(A7, FIND(",", A7)-1)) -> Anderson | D7: =IFERROR(DATEDIF(AB7, AC7, "Y"), DATEDIF(AB7, TODAY(), "Y")) -> 14 | E7: {=_xlfn.IFS(P7<40000, "Low", P7<70000, "MID", P7<100000, "HIGH", P7>=100000, "Executive")} -> MID | F7: {=_xlfn.IFS(AJ7="Exceeds", "Top Performer", AJ7="Fully Meets", "Solid Performer", AJ7="Needs Improvement", "Underperformer", AJ7="PIP", "At Risk")} -> Top Performer | G7: {=_xlfn.IFS(AE7="Active", "Retained", AE7="Voluntarily Terminated", "Voluntary Exit", AE7="Terminated for Cause", "Involuntary Exit")} -> Retained | H7: 10002 | I7: 0 | J7: 0 | K7: 0 | L7: 1 | M7: 5 | N7: 4 | O7: 0 | P7: 57568 | Q7: 0 | R7: 19 | S7: Production Technician I | T7: MA | U7: 1844 | V7: 28267 | W7: F | X7: Single | Y7: US Citizen | Z7: No | AA7: White | AB7: 40917 | AD7: N/A-StillEmployed | AE7: Active | AF7: Production | AG7: Amy Dunn | AH7: 11 | AI7: LinkedIn | AJ7: Exceeds | AK7: 5 | AL7: 5 | AM7: 0 | AN7: 43472 | AO7: 0 | AP7: 15
A8: Andreola, Colby | B8: =TRIM(MID(A8, FIND(",", A8)+1, LEN(A8))) -> Colby | C8: =TRIM(LEFT(A8, FIND(",", A8)-1)) -> Andreola | D8: =IFERROR(DATEDIF(AB8, AC8, "Y"), DATEDIF(AB8, TODAY(), "Y")) -> 11 | E8: {=_xlfn.IFS(P8<40000, "Low", P8<70000, "MID", P8<100000, "HIGH", P8>=100000, "Executive")} -> HIGH | F8: {=_xlfn.IFS(AJ8="Exceeds", "Top Performer", AJ8="Fully Meets", "Solid Performer", AJ8="Needs Improvement", "Underperformer", AJ8="PIP", "At Risk")} -> Solid Performer | G8: {=_xlfn.IFS(AE8="Active", "Retained", AE8="Voluntarily Terminated", "Voluntary Exit", AE8="Terminated for Cause", "Involuntary Exit")} -> Retained | H8: 10194 | I8: 0 | J8: 0 | K8: 0 | L8: 1 | M8: 4 | N8: 3 | O8: 0 | P8: 95660 | Q8: 0 | R8: 24 | S8: Software Engineer | T8: MA | U8: 2110 | V8: 28999 | W8: F | X8: Single | Y8: US Citizen | Z8: No | AA8: White | AB8: 41953 | AD8: N/A-StillEmployed | AE8: Active | AF8: Software Engineering | AG8: Alex Sweetwater | AH8: 10 | AI8: LinkedIn | AJ8: Fully Meets | AK8: 3.04 | AL8: 3 | AM8: 4 | AN8: 43467 | AO8: 0 | AP8: 19
A9: Athwal, Sam | B9: =TRIM(MID(A9, FIND(",", A9)+1, LEN(A9))) -> Sam | C9: =TRIM(LEFT(A9, FIND(",", A9)-1)) -> Athwal | D9: =IFERROR(DATEDIF(AB9, AC9, "Y"), DATEDIF(AB9, TODAY(), "Y")) -> 12 | E9: {=_xlfn.IFS(P9<40000, "Low", P9<70000, "MID", P9<100000, "HIGH", P9>=100000, "Executive")} -> MID | F9: {=_xlfn.IFS(AJ9="Exceeds", "Top Performer", AJ9="Fully Meets", "Solid Performer", AJ9="Needs Improvement", "Underperformer", AJ9="PIP", "At Risk")} -> Solid Performer | G9: {=_xlfn.IFS(AE9="Active", "Retained", AE9="Voluntarily Terminated", "Voluntary Exit", AE9="Terminated for Cause", "Involuntary Exit")} -> Retained | H9: 10062 | I9: 0 | J9: 4 | K9: 1 | L9: 1 | M9: 5 | N9: 3 | O9: 0 | P9: 59365 | Q9: 0 | R9: 19 | S9: Production Technician I | T9: MA | U9: 2199 | V9: 30365 | W9: M | X9: Widowed | Y9: US Citizen | Z9: No | AA9: White | AB9: 41547 | AD9: N/A-StillEmployed | AE9: Active | AF9: Production | AG9: Ketsia Liebig | AH9: 19 | AI9: Employee Referral | AJ9: Fully Meets | AK9: 5 | AL9: 4 | AM9: 0 | AN9: 43521 | AO9: 0 | AP9: 19
A10: Bachiochi, Linda | B10: =TRIM(MID(A10, FIND(",", A10)+1, LEN(A10))) -> Linda | C10: =TRIM(LEFT(A10, FIND(",", A10)-1)) -> Bachiochi | D10: =IFERROR(DATEDIF(AB10, AC10, "Y"), DATEDIF(AB10, TODAY(), "Y")) -> 16 | E10: {=_xlfn.IFS(P10<40000, "Low", P10<70000, "MID", P10<100000, "HIGH", P10>=100000, "Executive")} -> MID | F10: {=_xlfn.IFS(AJ10="Exceeds", "Top Performer", AJ10="Fully Meets", "Solid Performer", AJ10="Needs Improvement", "Underperformer", AJ10="PIP", "At Risk")} -> Solid Performer | G10: {=_xlfn.IFS(AE10="Active", "Retained", AE10="Voluntarily Terminated", "Voluntary Exit", AE10="Terminated for Cause", "Involuntary Exit")} -> Retained | H10: 10114 | I10: 0 | J10: 0 | K10: 0 | L10: 3 | M10: 5 | N10: 3 | O10: 1 | P10: 47837 | Q10: 0 | R10: 19 | S10: Production Technician I | T10: MA | U10: 1902 | V10: 25610 | W10: F | X10: Single | Y10: US Citizen | Z10: No | AA10: Black or African American | AB10: 40000 | AD10: N/A-StillEmployed | AE10: Active | AF10: Production | AG10: Brannon Miller | AH10: 12 | AI10: Diversity Job Fair | AJ10: Fully Meets | AK10: 4.46 | AL10: 3 | AM10: 0 | AN10: 43490 | AO10: 0 | AP10: 4
A11: Bacong, Alejandro | B11: =TRIM(MID(A11, FIND(",", A11)+1, LEN(A11))) -> Alejandro | C11: =TRIM(LEFT(A11, FIND(",", A11)-1)) -> Bacong | D11: =IFERROR(DATEDIF(AB11, AC11, "Y"), DATEDIF(AB11, TODAY(), "Y")) -> 11 | E11: {=_xlfn.IFS(P11<40000, "Low", P11<70000, "MID", P11<100000, "HIGH", P11>=100000, "Executive")} -> MID | F11: {=_xlfn.IFS(AJ11="Exceeds", "Top Performer", AJ11="Fully Meets", "Solid Performer", AJ11="Needs Improvement", "Underperformer", AJ11="PIP", "At Risk")} -> Solid Performer | G11: {=_xlfn.IFS(AE11="Active", "Retained", AE11="Voluntarily Terminated", "Voluntary Exit", AE11="Terminated for Cause", "Involuntary Exit")} -> Retained | H11: 10250 | I11: 0 | J11: 2 | K11: 1 | L11: 1 | M11: 3 | N11: 3 | O11: 0 | P11: 50178 | Q11: 0 | R11: 14 | S11: IT Support | T11: MA | U11: 1886 | V11: 32149 | W11: M | X11: Divorced | Y11: US Citizen | Z11: No | AA11: White | AB11: 42009 | AD11: N/A-StillEmployed | AE11: Active | AF11: IT/IS | AG11: Peter Monroe | AH11: 7 | AI11: Indeed | AJ11: Fully Meets | AK11: 5 | AL11: 5 | AM11: 6 | AN11: 43514 | AO11: 0 | AP11: 16
A12: Baczenski, Rachael | B12: =TRIM(MID(A12, FIND(",", A12)+1, LEN(A12))) -> Rachael | C12: =TRIM(LEFT(A12, FIND(",", A12)-1)) -> Baczenski | D12: =IFERROR(DATEDIF(AB12, AC12, "Y"), DATEDIF(AB12, TODAY(), "Y")) -> 6 | E12: {=_xlfn.IFS(P12<40000, "Low", P12<70000, "MID", P12<100000, "HIGH", P12>=100000, "Executive")} -> MID | F12: {=_xlfn.IFS(AJ12="Exceeds", "Top Performer", AJ12="Fully Meets", "Solid Performer", AJ12="Needs Improvement", "Underperformer", AJ12="PIP", "At Risk")} -> Solid Performer | G12: {=_xlfn.IFS(AE12="Active", "Retained", AE12="Voluntarily Terminated", "Voluntary Exit", AE12="Terminated for Cause", "Involuntary Exit")} -> Voluntary Exit | H12: 10252 | I12: 1 | J12: 1 | K12: 0 | L12: 5 | M12: 5 | N12: 3 | O12: 1 | P12: 54670 | Q12: 1 | R12: 19 | S12: Production Technician I | T12: MA | U12: 1902 | V12: 27041 | W12: F | X12: Married | Y12: US Citizen | Z12: Yes | AA12: Black or African American | AB12: 40553 | AC12: 42747 | AD12: Another position | AE12: Voluntarily Terminated | AF12: Production | AG12: David Stanley | AH12: 14 | AI12: Diversity Job Fair | AJ12: Fully Meets | AK12: 4.2 | AL12: 4 | AM12: 0 | AN12: 42399 | AO12: 0 | AP12: 12
A13: Barbara, Thomas | B13: =TRIM(MID(A13, FIND(",", A13)+1, LEN(A13))) -> Thomas | C13: =TRIM(LEFT(A13, FIND(",", A13)-1)) -> Barbara | D13: =IFERROR(DATEDIF(AB13, AC13, "Y"), DATEDIF(AB13, TODAY(), "Y")) -> 4 | E13: {=_xlfn.IFS(P13<40000, "Low", P13<70000, "MID", P13<100000, "HIGH", P13>=100000, "Executive")} -> MID | F13: {=_xlfn.IFS(AJ13="Exceeds", "Top Performer", AJ13="Fully Meets", "Solid Performer", AJ13="Needs Improvement", "Underperformer", AJ13="PIP", "At Risk")} -> Solid Performer | G13: {=_xlfn.IFS(AE13="Active", "Retained", AE13="Voluntarily Terminated", "Voluntary Exit", AE13="Terminated for Cause", "Involuntary Exit")} -> Voluntary Exit | H13: 10242 | I13: 1 | J13: 1 | K13: 1 | L13: 5 | M13: 5 | N13: 3 | O13: 1 | P13: 47211 | Q13: 1 | R13: 19 | S13: Production Technician I | T13: MA | U13: 2062 | V13: 27081 | W13: M | X13: Married | Y13: US Citizen | Z13: Yes | AA13: Black or African American | AB13: 41001 | AC13: 42632 | AD13: unhappy | AE13: Voluntarily Terminated | AF13: Production | AG13: Kissy Sullivan | AH13: 20 | AI13: Diversity Job Fair | AJ13: Fully Meets | AK13: 4.2 | AL13: 3 | AM13: 0 | AN13: 42496 | AO13: 0 | AP13: 15
A14: Barbossa, Hector | B14: =TRIM(MID(A14, FIND(",", A14)+1, LEN(A14))) -> Hector | C14: =TRIM(LEFT(A14, FIND(",", A14)-1)) -> Barbossa | D14: =IFERROR(DATEDIF(AB14, AC14, "Y"), DATEDIF(AB14, TODAY(), "Y")) -> 11 | E14: {=_xlfn.IFS(P14<40000, "Low", P14<70000, "MID", P14<100000, "HIGH", P14>=100000, "Executive")} -> HIGH | F14: {=_xlfn.IFS(AJ14="Exceeds", "Top Performer", AJ14="Fully Meets", "Solid Performer", AJ14="Needs Improvement", "Underperformer", AJ14="PIP", "At Risk")} -> Top Performer | G14: {=_xlfn.IFS(AE14="Active", "Retained", AE14="Voluntarily Terminated", "Voluntary Exit", AE14="Terminated for Cause", "Involuntary Exit")} -> Retained | H14: 10012 | I14: 0 | J14: 2 | K14: 1 | L14: 1 | M14: 3 | N14: 4 | O14: 1 | P14: 92328 | Q14: 0 | R14: 9 | S14: Data Analyst | T14: TX | U14: 78230 | V14: 32328 | W14: M | X14: Divorced | Y14: US Citizen | Z14: No | AA14: Black or African American | AB14: 41953 | AD14: N/A-StillEmployed | AE14: Active | AF14: IT/IS | AG14: Simon Roup | AH14: 4 | AI14: Diversity Job Fair | AJ14: Exceeds | AK14: 4.28 | AL14: 4 | AM14: 5 | AN14: 43521 | AO14: 0 | AP14: 9
A15: Barone, Francesco A | B15: =TRIM(MID(A15, FIND(",", A15)+1, LEN(A15))) -> Francesco A | C15: =TRIM(LEFT(A15, FIND(",", A15)-1)) -> Barone | D15: =IFERROR(DATEDIF(AB15, AC15, "Y"), DATEDIF(AB15, TODAY(), "Y")) -> 14 | E15: {=_xlfn.IFS(P15<40000, "Low", P15<70000, "MID", P15<100000, "HIGH", P15>=100000, "Executive")} -> MID | F15: {=_xlfn.IFS(AJ15="Exceeds", "Top Performer", AJ15="Fully Meets", "Solid Performer", AJ15="Needs Improvement", "Underperformer", AJ15="PIP", "At Risk")} -> Solid Performer | G15: {=_xlfn.IFS(AE15="Active", "Retained", AE15="Voluntarily Terminated", "Voluntary Exit", AE15="Terminated for Cause", "Involuntary Exit")} -> Retained | H15: 10265 | I15: 0 | J15: 0 | K15: 1 | L15: 1 | M15: 5 | N15: 3 | O15: 0 | P15: 58709 | Q15: 0 | R15: 19 | S15: Production Technician I | T15: MA | U15: 1810 | V15: 30517 | W15: M | X15: Single | Y15: US Citizen | Z15: No | AA15: Two or more races | AB15: 40959 | AD15: N/A-StillEmployed | AE15: Active | AF15: Production | AG15: Kelley Spirea | AH15: 18 | AI15: Google Search | AJ15: Fully Meets | AK15: 4.6 | AL15: 4 | AM15: 0 | AN15: 43510 | AO15: 0 | AP15: 7
A16: Barton, Nader | B16: =TRIM(MID(A16, FIND(",", A16)+1, LEN(A16))) -> Nader | C16: =TRIM(LEFT(A16, FIND(",", A16)-1)) -> Barton | D16: =IFERROR(DATEDIF(AB16, AC16, "Y"), DATEDIF(AB16, TODAY(), "Y")) -> 4 | E16: {=_xlfn.IFS(P16<40000, "Low", P16<70000, "MID", P16<100000, "HIGH", P16>=100000, "Executive")} -> MID | F16: {=_xlfn.IFS(AJ16="Exceeds", "Top Performer", AJ16="Fully Meets", "Solid Performer", AJ16="Needs Improvement", "Underperformer", AJ16="PIP", "At Risk")} -> Solid Performer | G16: {=_xlfn.IFS(AE16="Active", "Retained", AE16="Voluntarily Terminated", "Voluntary Exit", AE16="Terminated for Cause", "Involuntary Exit")} -> Voluntary Exit | H16: 10066 | I16: 0 | J16: 2 | K16: 1 | L16: 5 | M16: 5 | N16: 3 | O16: 0 | P16: 52505 | Q16: 1 | R16: 19 | S16: Production Technician I | T16: MA | U16: 2747 | V16: 28321 | W16: M | X16: Divorced | Y16: US Citizen | Z16: No | AA16: White | AB16: 41176 | AC16: 42831 | AD16: Another position | AE16: Voluntarily Terminated | AF16: Production | AG16: Michael Albert | AH16: 22 | AI16: On-line Web application | AJ16: Fully Meets | AK16: 5 | AL16: 5 | AM16: 0 | AN16: 42796 | AO16: 0 | AP16: 1
A17: Bates, Norman | B17: =TRIM(MID(A17, FIND(",", A17)+1, LEN(A17))) -> Norman | C17: =TRIM(LEFT(A17, FIND(",", A17)-1)) -> Bates | D17: =IFERROR(DATEDIF(AB17, AC17, "Y"), DATEDIF(AB17, TODAY(), "Y")) -> 6 | E17: {=_xlfn.IFS(P17<40000, "Low", P17<70000, "MID", P17<100000, "HIGH", P17>=100000, "Executive")} -> MID | F17: {=_xlfn.IFS(AJ17="Exceeds", "Top Performer", AJ17="Fully Meets", "Solid Performer", AJ17="Needs Improvement", "Underperformer", AJ17="PIP", "At Risk")} -> Solid Performer | G17: {=_xlfn.IFS(AE17="Active", "Retained", AE17="Voluntarily Terminated", "Voluntary Exit", AE17="Terminated for Cause", "Involuntary Exit")} -> Involuntary Exit | H17: 10061 | I17: 0 | J17: 0 | K17: 1 | L17: 4 | M17: 5 | N17: 3 | O17: 0 | P17: 57834 | Q17: 1 | R17: 19 | S17: Production Technician I | T17: MA | U17: 2050 | V17: 29877 | W17: M | X17: Single | Y17: US Citizen | Z17: No | AA17: White | AB17: 40595 | AC17: 42951 | AD17: attendance | AE17: Terminated for Cause | AF17: Production | AG17: Kelley Spirea | AH17: 18 | AI17: Google Search | AJ17: Fully Meets | AK17: 5 | AL17: 4 | AM17: 0 | AN17: 42830 | AO17: 0 | AP17: 20
A18: Beak, Kimberly | B18: =TRIM(MID(A18, FIND(",", A18)+1, LEN(A18))) -> Kimberly | C18: =TRIM(LEFT(A18, FIND(",", A18)-1)) -> Beak | D18: =IFERROR(DATEDIF(AB18, AC18, "Y"), DATEDIF(AB18, TODAY(), "Y")) -> 9 | E18: {=_xlfn.IFS(P18<40000, "Low", P18<70000, "MID", P18<100000, "HIGH", P18>=100000, "Executive")} -> HIGH | F18: {=_xlfn.IFS(AJ18="Exceeds", "Top Performer", AJ18="Fully Meets", "Solid Performer", AJ18="Needs Improvement", "Underperformer", AJ18="PIP", "At Risk")} -> Top Performer | G18: {=_xlfn.IFS(AE18="Active", "Retained", AE18="Voluntarily Terminated", "Voluntary Exit", AE18="Terminated for Cause", "Involuntary Exit")} -> Retained | H18: 10023 | I18: 1 | J18: 1 | K18: 0 | L18: 2 | M18: 5 | N18: 4 | O18: 0 | P18: 70131 | Q18: 0 | R18: 20 | S18: Production Technician II | T18: MA | U18: 2145 | V18: 24214 | W18: F | X18: Married | Y18: US Citizen | Z18: No | AA18: White | AB18: 42572 | AD18: N/A-StillEmployed | AE18: Active | AF18: Production | AG18: Kelley Spirea | AH18: 18 | AI18: Employee Referral | AJ18: Exceeds | AK18: 4.4 | AL18: 3 | AM18: 0 | AN18: 43479 | AO18: 0 | AP18: 16
A19: Beatrice, Courtney | B19: =TRIM(MID(A19, FIND(",", A19)+1, LEN(A19))) -> Courtney | C19: =TRIM(LEFT(A19, FIND(",", A19)-1)) -> Beatrice | D19: =IFERROR(DATEDIF(AB19, AC19, "Y"), DATEDIF(AB19, TODAY(), "Y")) -> 14 | E19: {=_xlfn.IFS(P19<40000, "Low", P19<70000, "MID", P19<100000, "HIGH", P19>=100000, "Executive")} -> MID | F19: {=_xlfn.IFS(AJ19="Exceeds", "Top Performer", AJ19="Fully Meets", "Solid Performer", AJ19="Needs Improvement", "Underperformer", AJ19="PIP", "At Risk")} -> Solid Performer | G19: {=_xlfn.IFS(AE19="Active", "Retained", AE19="Voluntarily Terminated", "Voluntary Exit", AE19="Terminated for Cause", "Involuntary Exit")} -> Retained | H19: 10055 | I19: 0 | J19: 0 | K19: 0 | L19: 1 | M19: 5 | N19: 3 | O19: 0 | P19: 59026 | Q19: 0 | R19: 19 | S19: Production Technician I | T19: MA | U19: 1915 | V19: 25868 | W19: F | X19: Single | Y19: Eligible NonCitizen | Z19: No | AA19: White | AB19: 40637 | AD19: N/A-StillEmployed | AE19: Active | AF19: Production | AG19: Elijiah Gray | AH19: 16 | AI19: Google Search | AJ19: Fully Meets | AK19: 5 | AL19: 5 | AM19: 0 | AN19: 43479 | AO19: 0 | AP19: 12
A20: Becker, Renee | B20: =TRIM(MID(A20, FIND(",", A20)+1, LEN(A20))) -> Renee | C20: =TRIM(LEFT(A20, FIND(",", A20)-1)) -> Becker | D20: =IFERROR(DATEDIF(AB20, AC20, "Y"), DATEDIF(AB20, TODAY(), "Y")) -> 1 | E20: {=_xlfn.IFS(P20<40000, "Low", P20<70000, "MID", P20<100000, "HIGH", P20>=100000, "Executive")} -> Executive | F20: {=_xlfn.IFS(AJ20="Exceeds", "Top Performer", AJ20="Fully Meets", "Solid Performer", AJ20="Needs Improvement", "Underperformer", AJ20="PIP", "At Risk")} -> Solid Performer | G20: {=_xlfn.IFS(AE20="Active", "Retained", AE20="Voluntarily Terminated", "Voluntary Exit", AE20="Terminated for Cause", "Involuntary Exit")} -> Involuntary Exit | H20: 10245 | I20: 0 | J20: 0 | K20: 0 | L20: 4 | M20: 3 | N20: 3 | O20: 0 | P20: 110000 | Q20: 1 | R20: 8 | S20: Database Administrator | T20: MA | U20: 2026 | V20: 31506 | W20: F | X20: Single | Y20: US Citizen | Z20: Yes | AA20: White | AB20: 41827 | AC20: 42259 | AD20: performance | AE20: Terminated for Cause | AF20: IT/IS | AG20: Simon Roup | AH20: 4 | AI20: Google Search | AJ20: Fully Meets | AK20: 4.5 | AL20: 4 | AM20: 5 | AN20: 42019 | AO20: 0 | AP20: 8
A21: Becker, Scott | B21: =TRIM(MID(A21, FIND(",", A21)+1, LEN(A21))) -> Scott | C21: =TRIM(LEFT(A21, FIND(",", A21)-1)) -> Becker | D21: =IFERROR(DATEDIF(AB21, AC21, "Y"), DATEDIF(AB21, TODAY(), "Y")) -> 12 | E21: {=_xlfn.IFS(P21<40000, "Low", P21<70000, "MID", P21<100000, "HIGH", P21>=100000, "Executive")} -> MID | F21: {=_xlfn.IFS(AJ21="Exceeds", "Top Performer", AJ21="Fully Meets", "Solid Performer", AJ21="Needs Improvement", "Underperformer", AJ21="PIP", "At Risk")} -> Solid Performer | G21: {=_xlfn.IFS(AE21="Active", "Retained", AE21="Voluntarily Terminated", "Voluntary Exit", AE21="Terminated for Cause", "Involuntary Exit")} -> Retained | H21: 10277 | I21: 0 | J21: 0 | K21: 1 | L21: 3 | M21: 5 | N21: 3 | O21: 0 | P21: 53250 | Q21: 0 | R21: 19 | S21: Production Technician I | T21: MA | U21: 2452 | V21: 28951 | W21: M | X21: Single | Y21: US Citizen | Z21: No | AA21: Asian | AB21: 41463 | AD21: N/A-StillEmployed | AE21: Active | AF21: Production | AG21: Webster Butler | AI21: LinkedIn | AJ21: Fully Meets | AK21: 4.2 | AL21: 4 | AM21: 0 | AN21: 43476 | AO21: 0 | AP21: 13
A22: Bernstein, Sean | B22: =TRIM(MID(A22, FIND(",", A22)+1, LEN(A22))) -> Sean | C22: =TRIM(LEFT(A22, FIND(",", A22)-1)) -> Bernstein | D22: =IFERROR(DATEDIF(AB22, AC22, "Y"), DATEDIF(AB22, TODAY(), "Y")) -> 14 | E22: {=_xlfn.IFS(P22<40000, "Low", P22<70000, "MID", P22<100000, "HIGH", P22>=100000, "Executive")} -> MID | F22: {=_xlfn.IFS(AJ22="Exceeds", "Top Performer", AJ22="Fully Meets", "Solid Performer", AJ22="Needs Improvement", "Underperformer", AJ22="PIP", "At Risk")} -> Solid Performer | G22: {=_xlfn.IFS(AE22="Active", "Retained", AE22="Voluntarily Terminated", "Voluntary Exit", AE22="Terminated for Cause", "Involuntary Exit")} -> Retained | H22: 10046 | I22: 0 | J22: 0 | K22: 1 | L22: 1 | M22: 5 | N22: 3 | O22: 0 | P22: 51044 | Q22: 0 | R22: 19 | S22: Production Technician I | T22: MA | U22: 2072 | V22: 25924 | W22: M | X22: Single | Y22: US Citizen | Z22: Yes | AA22: White | AB22: 41001 | AD22: N/A-StillEmployed | AE22: Active | AF22: Production | AG22: Amy Dunn | AH22: 11 | AI22: Google Search | AJ22: Fully Meets | AK22: 5 | AL22: 3 | AM22: 0 | AN22: 43479 | AO22: 0 | AP22: 13
A23: Biden, Lowan M | B23: =TRIM(MID(A23, FIND(",", A23)+1, LEN(A23))) -> Lowan M | C23: =TRIM(LEFT(A23, FIND(",", A23)-1)) -> Biden | D23: =IFERROR(DATEDIF(AB23, AC23, "Y"), DATEDIF(AB23, TODAY(), "Y")) -> 12 | E23: {=_xlfn.IFS(P23<40000, "Low", P23<70000, "MID", P23<100000, "HIGH", P23>=100000, "Executive")} -> MID | F23: {=_xlfn.IFS(AJ23="Exceeds", "Top Performer", AJ23="Fully Meets", "Solid Performer", AJ23="Needs Improvement", "Underperformer", AJ23="PIP", "At Risk")} -> Solid Performer | G23: {=_xlfn.IFS(AE23="Active", "Retained", AE23="Voluntarily Terminated", "Voluntary Exit", AE23="Terminated for Cause", "Involuntary Exit")} -> Retained | H23: 10226 | I23: 0 | J23: 2 | K23: 0 | L23: 1 | M23: 5 | N23: 3 | O23: 0 | P23: 64919 | Q23: 0 | R23: 19 | S23: Production Technician I | T23: MA | U23: 2027 | V23: 21546 | W23: F | X23: Divorced | Y23: US Citizen | Z23: No | AA23: Asian | AB23: 41505 | AD23: N/A-StillEmployed | AE23: Active | AF23: Production | AG23: Ketsia Liebig | AH23: 19 | AI23: Indeed | AJ23: Fully Meets | AK23: 4.2 | AL23: 3 | AM23: 0 | AN23: 43475 | AO23: 0 | AP23: 2
A24: Billis, Helen | B24: =TRIM(MID(A24, FIND(",", A24)+1, LEN(A24))) -> Helen | C24: =TRIM(LEFT(A24, FIND(",", A24)-1)) -> Billis | D24: =IFERROR(DATEDIF(AB24, AC24, "Y"), DATEDIF(AB24, TODAY(), "Y")) -> 11 | E24: {=_xlfn.IFS(P24<40000, "Low", P24<70000, "MID", P24<100000, "HIGH", P24>=100000, "Executive")} -> MID | F24: {=_xlfn.IFS(AJ24="Exceeds", "Top Performer", AJ24="Fully Meets", "Solid Performer", AJ24="Needs Improvement", "Underperformer", AJ24="PIP", "At Risk")} -> Top Performer | G24: {=_xlfn.IFS(AE24="Active", "Retained", AE24="Voluntarily Terminated", "Voluntary Exit", AE24="Terminated for Cause", "Involuntary Exit")} -> Retained | H24: 10003 | I24: 1 | J24: 1 | K24: 0 | L24: 1 | M24: 5 | N24: 4 | O24: 0 | P24: 62910 | Q24: 0 | R24: 19 | S24: Production Technician I | T24: MA | U24: 2031 | V24: 32752 | W24: F | X24: Married | Y24: US Citizen | Z24: No | AA24: White | AB24: 41827 | AD24: N/A-StillEmployed | AE24: Active | AF24: Production | AG24: Brannon Miller | AH24: 12 | AI24: Indeed | AJ24: Exceeds | AK24: 5 | AL24: 3 | AM24: 0 | AN24: 43523 | AO24: 0 | AP24: 19
A25: Blount, Dianna | B25: =TRIM(MID(A25, FIND(",", A25)+1, LEN(A25))) -> Dianna | C25: =TRIM(LEFT(A25, FIND(",", A25)-1)) -> Blount | D25: =IFERROR(DATEDIF(AB25, AC25, "Y"), DATEDIF(AB25, TODAY(), "Y")) -> 14 | E25: {=_xlfn.IFS(P25<40000, "Low", P25<70000, "MID", P25<100000, "HIGH", P25>=100000, "Executive")} -> MID | F25: {=_xlfn.IFS(AJ25="Exceeds", "Top Performer", AJ25="Fully Meets", "Solid Performer", AJ25="Needs Improvement", "Underperformer", AJ25="PIP", "At Risk")} -> Underperformer | G25: {=_xlfn.IFS(AE25="Active", "Retained", AE25="Voluntarily Terminated", "Voluntary Exit", AE25="Terminated for Cause", "Involuntary Exit")} -> Retained | H25: 10294 | I25: 0 | J25: 0 | K25: 0 | L25: 1 | M25: 5 | N25: 2 | O25: 0 | P25: 66441 | Q25: 0 | R25: 20 | S25: Production Technician II | T25: MA | U25: 2171 | V25: 33137 | W25: F | X25: Single | Y25: US Citizen | Z25: No | AA25: White | AB25: 40637 | AD25: N/A-StillEmployed | AE25: Active | AF25: Production | AG25: Michael Albert | AH25: 22 | AI25: CareerBuilder | AJ25: Needs Improvement | AK25: 2 | AL25: 3 | AM25: 0 | AN25: 43523 | AO25: 2 | AP25: 3
A26: Bondwell, Betsy | B26: =TRIM(MID(A26, FIND(",", A26)+1, LEN(A26))) -> Betsy | C26: =TRIM(LEFT(A26, FIND(",", A26)-1)) -> Bondwell | D26: =IFERROR(DATEDIF(AB26, AC26, "Y"), DATEDIF(AB26, TODAY(), "Y")) -> 3 | E26: {=_xlfn.IFS(P26<40000, "Low", P26<70000, "MID", P26<100000, "HIGH", P26>=100000, "Executive")} -> MID | F26: {=_xlfn.IFS(AJ26="Exceeds", "Top Performer", AJ26="Fully Meets", "Solid Performer", AJ26="Needs Improvement", "Underperformer", AJ26="PIP", "At Risk")} -> Solid Performer | G26: {=_xlfn.IFS(AE26="Active", "Retained", AE26="Voluntarily Terminated", "Voluntary Exit", AE26="Terminated for Cause", "Involuntary Exit")} -> Voluntary Exit | H26: 10267 | I26: 0 | J26: 0 | K26: 0 | L26: 5 | M26: 5 | N26: 3 | O26: 0 | P26: 57815 | Q26: 1 | R26: 20 | S26: Production Technician II | T26: MA | U26: 2210 | V26: 24488 | W26: F | X26: Single | Y26: US Citizen | Z26: No | AA26: White | AB26: 40553 | AC26: 41733 | AD26: career change | AE26: Voluntarily Terminated | AF26: Production | AG26: Elijiah Gray | AH26: 16 | AI26: Google Search | AJ26: Fully Meets | AK26: 4.8 | AL26: 5 | AM26: 0 | AN26: 41702 | AO26: 0 | AP26: 5
A27: Booth, Frank | B27: =TRIM(MID(A27, FIND(",", A27)+1, LEN(A27))) -> Frank | C27: =TRIM(LEFT(A27, FIND(",", A27)-1)) -> Booth | D27: =IFERROR(DATEDIF(AB27, AC27, "Y"), DATEDIF(AB27, TODAY(), "Y")) -> 2 | E27: {=_xlfn.IFS(P27<40000, "Low", P27<70000, "MID", P27<100000, "HIGH", P27>=100000, "Executive")} -> Executive | F27: {=_xlfn.IFS(AJ27="Exceeds", "Top Performer", AJ27="Fully Meets", "Solid Performer", AJ27="Needs Improvement", "Underperformer", AJ27="PIP", "At Risk")} -> Solid Performer | G27: {=_xlfn.IFS(AE27="Active", "Retained", AE27="Voluntarily Terminated", "Voluntary Exit", AE27="Terminated for Cause", "Involuntary Exit")} -> Involuntary Exit | H27: 10199 | I27: 0 | J27: 0 | K27: 1 | L27: 4 | M27: 3 | N27: 3 | O27: 0 | P27: 103613 | Q27: 1 | R27: 30 | S27: Enterprise Architect | T27: CT | U27: 6033 | V27: 23588 | W27: M | X27: Single | Y27: US Citizen | Z27: No | AA27: Black or African American | AB27: 41687 | AC27: 42419 | AD27: Learned that he is a gangster | AE27: Terminated for Cause | AF27: IT/IS | AG27: Simon Roup | AH27: 4 | AI27: LinkedIn | AJ27: Fully Meets | AK27: 3.5 | AL27: 5 | AM27: 7 | AN27: 42379 | AO27: 0 | AP27: 2
A28: Boutwell, Bonalyn | B28: =TRIM(MID(A28, FIND(",", A28)+1, LEN(A28))) -> Bonalyn | C28: =TRIM(LEFT(A28, FIND(",", A28)-1)) -> Boutwell | D28: =IFERROR(DATEDIF(AB28, AC28, "Y"), DATEDIF(AB28, TODAY(), "Y")) -> 11 | E28: {=_xlfn.IFS(P28<40000, "Low", P28<70000, "MID", P28<100000, "HIGH", P28>=100000, "Executive")} -> Executive | F28: {=_xlfn.IFS(AJ28="Exceeds", "Top Performer", AJ28="Fully Meets", "Solid Performer", AJ28="Needs Improvement", "Underperformer", AJ28="PIP", "At Risk")} -> Solid Performer | G28: {=_xlfn.IFS(AE28="Active", "Retained", AE28="Voluntarily Terminated", "Voluntary Exit", AE28="Terminated for Cause", "Involuntary Exit")} -> Retained | H28: 10081 | I28: 1 | J28: 1 | K28: 0 | L28: 1 | M28: 1 | N28: 3 | O28: 1 | P28: 106367 | Q28: 0 | R28: 26 | S28: Sr. Accountant | T28: MA | U28: 2468 | V28: 31871 | W28: F | X28: Married | Y28: US Citizen | Z28: No | AA28: Black or African American | AB28: 42051 | AD28: N/A-StillEmployed | AE28: Active | AF28: Admin Offices | AG28: Brandon R. LeBlanc | AH28: 3 | AI28: Diversity Job Fair | AJ28: Fully Meets | AK28: 5 | AL28: 4 | AM28: 3 | AN28: 43514 | AO28: 0 | AP28: 4
A29: Bozzi, Charles | B29: =TRIM(MID(A29, FIND(",", A29)+1, LEN(A29))) -> Charles | C29: =TRIM(LEFT(A29, FIND(",", A29)-1)) -> Bozzi | D29: =IFERROR(DATEDIF(AB29, AC29, "Y"), DATEDIF(AB29, TODAY(), "Y")) -> 0 | E29: {=_xlfn.IFS(P29<40000, "Low", P29<70000, "MID", P29<100000, "HIGH", P29>=100000, "Executive")} -> HIGH | F29: {=_xlfn.IFS(AJ29="Exceeds", "Top Performer", AJ29="Fully Meets", "Solid Performer", AJ29="Needs Improvement", "Underperformer", AJ29="PIP", "At Risk")} -> Solid Performer | G29: {=_xlfn.IFS(AE29="Active", "Retained", AE29="Voluntarily Terminated", "Voluntary Exit", AE29="Terminated for Cause", "Involuntary Exit")} -> Voluntary Exit | H29: 10175 | I29: 0 | J29: 0 | K29: 1 | L29: 5 | M29: 5 | N29: 3 | O29: 0 | P29: 74312 | Q29: 1 | R29: 18 | S29: Production Manager | T29: MA | U29: 1901 | V29: 25637 | W29: M | X29: Single | Y29: US Citizen | Z29: No | AA29: Asian | AB29: 41547 | AC29: 41858 | AD29: retiring | AE29: Voluntarily Terminated | AF29: Production | AG29: Janet King | AH29: 2 | AI29: Indeed | AJ29: Fully Meets | AK29: 3.39 | AL29: 3 | AM29: 0 | AN29: 41690 | AO29: 0 | AP29: 14
A30: Brill, Donna | B30: =TRIM(MID(A30, FIND(",", A30)+1, LEN(A30))) -> Donna | C30: =TRIM(LEFT(A30, FIND(",", A30)-1)) -> Brill | D30: =IFERROR(DATEDIF(AB30, AC30, "Y"), DATEDIF(AB30, TODAY(), "Y")) -> 1 | E30: {=_xlfn.IFS(P30<40000, "Low", P30<70000, "MID", P30<100000, "HIGH", P30>=100000, "Executive")} -> MID | F30: {=_xlfn.IFS(AJ30="Exceeds", "Top Performer", AJ30="Fully Meets", "Solid Performer", AJ30="Needs Improvement", "Underperformer", AJ30="PIP", "At Risk")} -> Solid Performer | G30: {=_xlfn.IFS(AE30="Active", "Retained", AE30="Voluntarily Terminated", "Voluntary Exit", AE30="Terminated for Cause", "Involuntary Exit")} -> Voluntary Exit | H30: 10177 | I30: 1 | J30: 1 | K30: 0 | L30: 5 | M30: 5 | N30: 3 | O30: 0 | P30: 53492 | Q30: 1 | R30: 19 | S30: Production Technician I | T30: MA | U30: 1701 | V30: 33109 | W30: F | X30: Married | Y30: US Citizen | Z30: No | AA30: White | AB30: 41001 | AC30: 41440 | AD30: Another position | AE30: Voluntarily Terminated | AF30: Production | AG30: David Stanley | AH30: 14 | AI30: Google Search | AJ30: Fully Meets | AK30: 3.35 | AL30: 4 | AM30: 0 | AN30: 41337 | AO30: 0 | AP30: 6
A31: Brown, Mia | B31: =TRIM(MID(A31, FIND(",", A31)+1, LEN(A31))) -> Mia | C31: =TRIM(LEFT(A31, FIND(",", A31)-1)) -> Brown | D31: =IFERROR(DATEDIF(AB31, AC31, "Y"), DATEDIF(AB31, TODAY(), "Y")) -> 17 | E31: {=_xlfn.IFS(P31<40000, "Low", P31<70000, "MID", P31<100000, "HIGH", P31>=100000, "Executive")} -> MID | F31: {=_xlfn.IFS(AJ31="Exceeds", "Top Performer", AJ31="Fully Meets", "Solid Performer", AJ31="Needs Improvement", "Underperformer", AJ31="PIP", "At Risk")} -> Solid Performer | G31: {=_xlfn.IFS(AE31="Active", "Retained", AE31="Voluntarily Terminated", "Voluntary Exit", AE31="Terminated for Cause", "Involuntary Exit")} -> Retained | H31: 10238 | I31: 1 | J31: 1 | K31: 0 | L31: 1 | M31: 1 | N31: 3 | O31: 1 | P31: 63000 | Q31: 0 | R31: 1 | S31: Accountant I | T31: MA | U31: 1450 | V31: 32105 | W31: F | X31: Married | Y31: US Citizen | Z31: No | AA31: Black or African American | AB31: 39748 | AD31: N/A-StillEmployed | AE31: Active | AF31: Admin Offices | AG31: Brandon R. LeBlanc | AH31: 1 | AI31: Diversity Job Fair | AJ31: Fully Meets | AK31: 4.5 | AL31: 2 | AM31: 6 | AN31: 43480 | AO31: 0 | AP31: 14
A32: Buccheri, Joseph | B32: =TRIM(MID(A32, FIND(",", A32)+1, LEN(A32))) -> Joseph | C32: =TRIM(LEFT(A32, FIND(",", A32)-1)) -> Buccheri | D32: =IFERROR(DATEDIF(AB32, AC32, "Y"), DATEDIF(AB32, TODAY(), "Y")) -> 11 | E32: {=_xlfn.IFS(P32<40000, "Low", P32<70000, "MID", P32<100000, "HIGH", P32>=100000, "Executive")} -> MID | F32: {=_xlfn.IFS(AJ32="Exceeds", "Top Performer", AJ32="Fully Meets", "Solid Performer", AJ32="Needs Improvement", "Underperformer", AJ32="PIP", "At Risk")} -> Solid Performer | G32: {=_xlfn.IFS(AE32="Active", "Retained", AE32="Voluntarily Terminated", "Voluntary Exit", AE32="Terminated for Cause", "Involuntary Exit")} -> Retained | H32: 10184 | I32: 0 | J32: 0 | K32: 1 | L32: 1 | M32: 5 | N32: 3 | O32: 0 | P32: 65288 | Q32: 0 | R32: 20 | S32: Production Technician II | T32: MA | U32: 1013 | V32: 30525 | W32: M | X32: Single | Y32: US Citizen | Z32: No | AA32: White | AB32: 41911 | AD32: N/A-StillEmployed | AE32: Active | AF32: Production | AG32: Webster Butler | AI32: Google Search | AJ32: Fully Meets | AK32: 3.19 | AL32: 3 | AM32: 0 | AN32: 43497 | AO32: 0 | AP32: 9
A33: Bugali, Josephine | B33: =TRIM(MID(A33, FIND(",", A33)+1, LEN(A33))) -> Josephine | C33: =TRIM(LEFT(A33, FIND(",", A33)-1)) -> Bugali | D33: =IFERROR(DATEDIF(AB33, AC33, "Y"), DATEDIF(AB33, TODAY(), "Y")) -> 12 | E33: {=_xlfn.IFS(P33<40000, "Low", P33<70000, "MID", P33<100000, "HIGH", P33>=100000, "Executive")} -> MID | F33: {=_xlfn.IFS(AJ33="Exceeds", "Top Performer", AJ33="Fully Meets", "Solid Performer", AJ33="Needs Improvement", "Underperformer", AJ33="PIP", "At Risk")} -> Solid Performer | G33: {=_xlfn.IFS(AE33="Active", "Retained", AE33="Voluntarily Terminated", "Voluntary Exit", AE33="Terminated for Cause", "Involuntary Exit")} -> Retained | H33: 10203 | I33: 0 | J33: 3 | K33: 0 | L33: 3 | M33: 5 | N33: 3 | O33: 1 | P33: 64375 | Q33: 0 | R33: 19 | S33: Production Technician I | T33: MA | U33: 2043 | V33: 25506 | W33: F | X33: Separated | Y33: US Citizen | Z33: No | AA33: Black or African American | AB33: 41589 | AD33: N/A-StillEmployed | AE33: Active | AF33: Production | AG33: Kissy Sullivan | AH33: 20 | AI33: Diversity Job Fair | AJ33: Fully Meets | AK33: 3.5 | AL33: 5 | AM33: 0 | AN33: 43486 | AO33: 0 | AP33: 17
A34: Bunbury, Jessica | B34: =TRIM(MID(A34, FIND(",", A34)+1, LEN(A34))) -> Jessica | C34: =TRIM(LEFT(A34, FIND(",", A34)-1)) -> Bunbury | D34: =IFERROR(DATEDIF(AB34, AC34, "Y"), DATEDIF(AB34, TODAY(), "Y")) -> 2 | E34: {=_xlfn.IFS(P34<40000, "Low", P34<70000, "MID", P34<100000, "HIGH", P34>=100000, "Executive")} -> HIGH | F34: {=_xlfn.IFS(AJ34="Exceeds", "Top Performer", AJ34="Fully Meets", "Solid Performer", AJ34="Needs Improvement", "Underperformer", AJ34="PIP", "At Risk")} -> Solid Performer | G34: {=_xlfn.IFS(AE34="Active", "Retained", AE34="Voluntarily Terminated", "Voluntary Exit", AE34="Terminated for Cause", "Involuntary Exit")} -> Voluntary Exit | H34: 10188 | I34: 1 | J34: 1 | K34: 0 | L34: 5 | M34: 6 | N34: 3 | O34: 0 | P34: 74326 | Q34: 1 | R34: 3 | S34: Area Sales Manager | T34: VA | U34: 21851 | V34: 23529 | W34: F | X34: Married | Y34: Eligible NonCitizen | Z34: No | AA34: Black or African American | AB34: 40770 | AC34: 41853 | AD34: Another position | AE34: Voluntarily Terminated | AF34: Sales | AG34: John Smith | AH34: 17 | AI34: Google Search | AJ34: Fully Meets | AK34: 3.14 | AL34: 5 | AM34: 0 | AN34: 41315 | AO34: 1 | AP34: 19
A35: Burke, Joelle | B35: =TRIM(MID(A35, FIND(",", A35)+1, LEN(A35))) -> Joelle | C35: =TRIM(LEFT(A35, FIND(",", A35)-1)) -> Burke | D35: =IFERROR(DATEDIF(AB35, AC35, "Y"), DATEDIF(AB35, TODAY(), "Y")) -> 14 | E35: {=_xlfn.IFS(P35<40000, "Low", P35<70000, "MID", P35<100000, "HIGH", P35>=100000, "Executive")} -> MID | F35: {=_xlfn.IFS(AJ35="Exceeds", "Top Performer", AJ35="Fully Meets", "Solid Performer", AJ35="Needs Improvement", "Underperformer", AJ35="PIP", "At Risk")} -> Solid Performer | G35: {=_xlfn.IFS(AE35="Active", "Retained", AE35="Voluntarily Terminated", "Voluntary Exit", AE35="Terminated for Cause", "Involuntary Exit")} -> Retained | H35: 10107 | I35: 0 | J35: 0 | K35: 0 | L35: 1 | M35: 5 | N35: 3 | O35: 0 | P35: 63763 | Q35: 0 | R35: 20 | S35: Production Technician II | T35: MA | U35: 2148 | V35: 29282 | W35: F | X35: Single | Y35: US Citizen | Z35: No | AA35: Black or African American | AB35: 40973 | AD35: N/A-StillEmployed | AE35: Active | AF35: Production | AG35: Amy Dunn | AH35: 11 | AI35: Employee Referral | AJ35: Fully Meets | AK35: 4.51 | AL35: 4 | AM35: 0 | AN35: 43517 | AO35: 0 | AP35: 3
A36: Burkett, Benjamin | B36: =TRIM(MID(A36, FIND(",", A36)+1, LEN(A36))) -> Benjamin | C36: =TRIM(LEFT(A36, FIND(",", A36)-1)) -> Burkett | D36: =IFERROR(DATEDIF(AB36, AC36, "Y"), DATEDIF(AB36, TODAY(), "Y")) -> 14 | E36: {=_xlfn.IFS(P36<40000, "Low", P36<70000, "MID", P36<100000, "HIGH", P36>=100000, "Executive")} -> MID | F36: {=_xlfn.IFS(AJ36="Exceeds", "Top Performer", AJ36="Fully Meets", "Solid Performer", AJ36="Needs Improvement", "Underperformer", AJ36="PIP", "At Risk")} -> Solid Performer | G36: {=_xlfn.IFS(AE36="Active", "Retained", AE36="Voluntarily Terminated", "Voluntary Exit", AE36="Terminated for Cause", "Involuntary Exit")} -> Retained | H36: 10181 | I36: 1 | J36: 1 | K36: 1 | L36: 1 | M36: 5 | N36: 3 | O36: 0 | P36: 62162 | Q36: 0 | R36: 20 | S36: Production Technician II | T36: MA | U36: 1890 | V36: 28356 | W36: M | X36: Married | Y36: US Citizen | Z36: No | AA36: White | AB36: 40637 | AD36: N/A-StillEmployed | AE36: Active | AF36: Production | AG36: Ketsia Liebig | AH36: 19 | AI36: Indeed | AJ36: Fully Meets | AK36: 3.25 | AL36: 5 | AM36: 0 | AN36: 43479 | AO36: 0 | AP36: 15
A37: Cady, Max | B37: =TRIM(MID(A37, FIND(",", A37)+1, LEN(A37))) -> Max | C37: =TRIM(LEFT(A37, FIND(",", A37)-1)) -> Cady | D37: =IFERROR(DATEDIF(AB37, AC37, "Y"), DATEDIF(AB37, TODAY(), "Y")) -> 14 | E37: {=_xlfn.IFS(P37<40000, "Low", P37<70000, "MID", P37<100000, "HIGH", P37>=100000, "Executive")} -> HIGH | F37: {=_xlfn.IFS(AJ37="Exceeds", "Top Performer", AJ37="Fully Meets", "Solid Performer", AJ37="Needs Improvement", "Underperformer", AJ37="PIP", "At Risk")} -> Solid Performer | G37: {=_xlfn.IFS(AE37="Active", "Retained", AE37="Voluntarily Terminated", "Voluntary Exit", AE37="Terminated for Cause", "Involuntary Exit")} -> Retained | H37: 10150 | I37: 0 | J37: 0 | K37: 1 | L37: 1 | M37: 4 | N37: 3 | O37: 0 | P37: 77692 | Q37: 0 | R37: 25 | S37: Software Engineering Manager | T37: MA | U37: 2184 | V37: 24433 | W37: M | X37: Single | Y37: US Citizen | Z37: No | AA37: White | AB37: 40770 | AD37: N/A-StillEmployed | AE37: Active | AF37: Software Engineering | AG37: Jennifer Zamora | AH37: 5 | AI37: Google Search | AJ37: Fully Meets | AK37: 3.84 | AL37: 3 | AM37: 5 | AN37: 43486 | AO37: 0 | AP37: 4
A38: Candie, Calvin | B38: =TRIM(MID(A38, FIND(",", A38)+1, LEN(A38))) -> Calvin | C38: =TRIM(LEFT(A38, FIND(",", A38)-1)) -> Candie | D38: =IFERROR(DATEDIF(AB38, AC38, "Y"), DATEDIF(AB38, TODAY(), "Y")) -> 10 | E38: {=_xlfn.IFS(P38<40000, "Low", P38<70000, "MID", P38<100000, "HIGH", P38>=100000, "Executive")} -> HIGH | F38: {=_xlfn.IFS(AJ38="Exceeds", "Top Performer", AJ38="Fully Meets", "Solid Performer", AJ38="Needs Improvement", "Underperformer", AJ38="PIP", "At Risk")} -> Top Performer | G38: {=_xlfn.IFS(AE38="Active", "Retained", AE38="Voluntarily Terminated", "Voluntary Exit", AE38="Terminated for Cause", "Involuntary Exit")} -> Retained | H38: 10001 | I38: 0 | J38: 0 | K38: 1 | L38: 1 | M38: 5 | N38: 4 | O38: 0 | P38: 72640 | Q38: 0 | R38: 18 | S38: Production Manager | T38: MA | U38: 2169 | V38: 30537 | W38: M | X38: Single | Y38: US Citizen | Z38: No | AA38: White | AB38: 42397 | AD38: N/A-StillEmployed | AE38: Active | AF38: Production | AG38: Janet King | AH38: 2 | AI38: Indeed | AJ38: Exceeds | AK38: 5 | AL38: 3 | AM38: 0 | AN38: 43518 | AO38: 0 | AP38: 14
A39: Carabbio, Judith | B39: =TRIM(MID(A39, FIND(",", A39)+1, LEN(A39))) -> Judith | C39: =TRIM(LEFT(A39, FIND(",", A39)-1)) -> Carabbio | D39: =IFERROR(DATEDIF(AB39, AC39, "Y"), DATEDIF(AB39, TODAY(), "Y")) -> 12 | E39: {=_xlfn.IFS(P39<40000, "Low", P39<70000, "MID", P39<100000, "HIGH", P39>=100000, "Executive")} -> HIGH | F39: {=_xlfn.IFS(AJ39="Exceeds", "Top Performer", AJ39="Fully Meets", "Solid Performer", AJ39="Needs Improvement", "Underperformer", AJ39="PIP", "At Risk")} -> Solid Performer | G39: {=_xlfn.IFS(AE39="Active", "Retained", AE39="Voluntarily Terminated", "Voluntary Exit", AE39="Terminated for Cause", "Involuntary Exit")} -> Retained | H39: 10085 | I39: 0 | J39: 0 | K39: 0 | L39: 1 | M39: 4 | N39: 3 | O39: 0 | P39: 93396 | Q39: 0 | R39: 24 | S39: Software Engineer | T39: MA | U39: 2132 | V39: 31872 | W39: F | X39: Single | Y39: US Citizen | Z39: No | AA39: White | AB39: 41589 | AD39: N/A-StillEmployed | AE39: Active | AF39: Software Engineering | AG39: Alex Sweetwater | AH39: 10 | AI39: Indeed | AJ39: Fully Meets | AK39: 4.96 | AL39: 4 | AM39: 6 | AN39: 43495 | AO39: 0 | AP39: 3
A40: Carey, Michael | B40: =TRIM(MID(A40, FIND(",", A40)+1, LEN(A40))) -> Michael | C40: =TRIM(LEFT(A40, FIND(",", A40)-1)) -> Carey | D40: =IFERROR(DATEDIF(AB40, AC40, "Y"), DATEDIF(AB40, TODAY(), "Y")) -> 12 | E40: {=_xlfn.IFS(P40<40000, "Low", P40<70000, "MID", P40<100000, "HIGH", P40>=100000, "Executive")} -> MID | F40: {=_xlfn.IFS(AJ40="Exceeds", "Top Performer", AJ40="Fully Meets", "Solid Performer", AJ40="Needs Improvement", "Underperformer", AJ40="PIP", "At Risk")} -> Solid Performer | G40: {=_xlfn.IFS(AE40="Active", "Retained", AE40="Voluntarily Terminated", "Voluntary Exit", AE40="Terminated for Cause", "Involuntary Exit")} -> Retained | H40: 10115 | I40: 0 | J40: 0 | K40: 1 | L40: 1 | M40: 5 | N40: 3 | O40: 0 | P40: 52846 | Q40: 0 | R40: 19 | S40: Production Technician I | T40: MA | U40: 1701 | V40: 30349 | W40: M | X40: Single | Y40: US Citizen | Z40: No | AA40: Black or African American | AB40: 41729 | AD40: N/A-StillEmployed | AE40: Active | AF40: Production | AG40: Kelley Spirea | AH40: 18 | AI40: LinkedIn | AJ40: Fully Meets | AK40: 4.43 | AL40: 3 | AM40: 0 | AN40: 43497 | AO40: 0 | AP40: 14
...

Sheet Analysis
A1: {=_xlfn.UNIQUE(Employee_Data!AF:AF)} -> Department | B1: Employee_Count | C1: Total_Salary | D1: Average_Salary | E1: Employees_Who_Left | F1: Turnover_Rate | G1: Average_Tenure_Years | H1: Average_Engagement_Score
A2: Production | B2: =COUNTIF(Employee_Data!AF:AF, A2) -> 209 | C2: =SUMIF(Employee_Data!AF:AF, A2, Employee_Data!P:P) -> 12530291 | D2: =AVERAGEIF(Employee_Data!AF:AF, A2, Employee_Data!P:P) -> 59953.545 | E2: =COUNTIFS(Employee_Data!AF:AF, A2, Employee_Data!Q:Q, 1) -> 83 | F2: =(E2/B2) -> 0.39712919 | G2: =AVERAGEIF(Employee_Data!AF:AF, A2, Employee_Data!D:D) -> 8.7751196 | H2: =AVERAGEIF(Employee_Data!AF:AF, A2, Employee_Data!AK:AK) -> 4.1295694
A3: IT/IS | B3: =COUNTIF(Employee_Data!AF:AF, A3) -> 50 | C3: =SUMIF(Employee_Data!AF:AF, A3, Employee_Data!P:P) -> 4853232 | D3: =AVERAGEIF(Employee_Data!AF:AF, A3, Employee_Data!P:P) -> 97064.64 | E3: =COUNTIFS(Employee_Data!AF:AF, A3, Employee_Data!Q:Q, 1) -> 10 | F3: =(E3/B3) -> 0.2 | G3: =AVERAGEIF(Employee_Data!AF:AF, A3, Employee_Data!D:D) -> 9.12 | H3: =AVERAGEIF(Employee_Data!AF:AF, A3, Employee_Data!AK:AK) -> 4.154
A4: Software Engineering | B4: =COUNTIF(Employee_Data!AF:AF, A4) -> 11 | C4: =SUMIF(Employee_Data!AF:AF, A4, Employee_Data!P:P) -> 1044884 | D4: =AVERAGEIF(Employee_Data!AF:AF, A4, Employee_Data!P:P) -> 94989.455 | E4: =COUNTIFS(Employee_Data!AF:AF, A4, Employee_Data!Q:Q, 1) -> 4 | F4: =(E4/B4) -> 0.36363636 | G4: =AVERAGEIF(Employee_Data!AF:AF, A4, Employee_Data!D:D) -> 9.1818182 | H4: =AVERAGEIF(Employee_Data!AF:AF, A4, Employee_Data!AK:AK) -> 4.0618182
A5: Admin Offices | B5: =COUNTIF(Employee_Data!AF:AF, A5) -> 9 | C5: =SUMIF(Employee_Data!AF:AF, A5, Employee_Data!P:P) -> 646127 | D5: =AVERAGEIF(Employee_Data!AF:AF, A5, Employee_Data!P:P) -> 71791.889 | E5: =COUNTIFS(Employee_Data!AF:AF, A5, Employee_Data!Q:Q, 1) -> 2 | F5: =(E5/B5) -> 0.22222222 | G5: =AVERAGEIF(Employee_Data!AF:AF, A5, Employee_Data!D:D) -> 9.8888889 | H5: =AVERAGEIF(Employee_Data!AF:AF, A5, Employee_Data!AK:AK) -> 4.3933333
A6: Sales | B6: =COUNTIF(Employee_Data!AF:AF, A6) -> 31 | C6: =SUMIF(Employee_Data!AF:AF, A6, Employee_Data!P:P) -> 2140899 | D6: =AVERAGEIF(Employee_Data!AF:AF, A6, Employee_Data!P:P) -> 69061.258 | E6: =COUNTIFS(Employee_Data!AF:AF, A6, Employee_Data!Q:Q, 1) -> 5 | F6: =(E6/B6) -> 0.16129032 | G6: =AVERAGEIF(Employee_Data!AF:AF, A6, Employee_Data!D:D) -> 10.870968 | H6: =AVERAGEIF(Employee_Data!AF:AF, A6, Employee_Data!AK:AK) -> 3.8187097
A7: Executive Office | B7: =COUNTIF(Employee_Data!AF:AF, A7) -> 1 | C7: =SUMIF(Employee_Data!AF:AF, A7, Employee_Data!P:P) -> 250000 | D7: =AVERAGEIF(Employee_Data!AF:AF, A7, Employee_Data!P:P) -> 250000 | E7: =COUNTIFS(Employee_Data!AF:AF, A7, Employee_Data!Q:Q, 1) -> 0 | F7: =(E7/B7) -> 0 | G7: =AVERAGEIF(Employee_Data!AF:AF, A7, Employee_Data!D:D) -> 13 | H7: =AVERAGEIF(Employee_Data!AF:AF, A7, Employee_Data!AK:AK) -> 4.83
A8: 0

Sheet Lookup_Table
A1: EmpID | B1: Salary_Band | C1: Performance_Category | D1: Attrition_Type | E1: DateofTermination | F1: TermReason | G1: EmploymentStatus | H1: Department | I1: ManagerName | J1: ManagerID | K1: RecruitmentSource | L1: PerformanceScore | M1: EngagementSurvey | N1: EmpSatisfaction
A2: 10026 | B2: MID | C2: {=_xlfn.IFS(L2="Exceeds", "Top Performer", L2="Fully Meets", "Solid Performer", L2="Needs Improvement", "Underperformer", L2="PIP", "At Risk")} -> Top Performer | D2: {=_xlfn.IFS(G2="Active", "Retained", G2="Voluntarily Terminated", "Voluntary Exit", G2="Terminated for Cause", "Involuntary Exit")} -> Retained | F2: N/A-StillEmployed | G2: Active | H2: Production | I2: Michael Albert | J2: 22 | K2: LinkedIn | L2: Exceeds | M2: 4.6 | N2: 5
A3: 10084 | B3: Executive | C3: {=_xlfn.IFS(L3="Exceeds", "Top Performer", L3="Fully Meets", "Solid Performer", L3="Needs Improvement", "Underperformer", L3="PIP", "At Risk")} -> Solid Performer | D3: {=_xlfn.IFS(G3="Active", "Retained", G3="Voluntarily Terminated", "Voluntary Exit", G3="Terminated for Cause", "Involuntary Exit")} -> Voluntary Exit | E3: 42537 | F3: career change | G3: Voluntarily Terminated | H3: IT/IS | I3: Simon Roup | J3: 4 | K3: Indeed | L3: Fully Meets | M3: 4.96 | N3: 3
A4: 10196 | B4: MID | C4: {=_xlfn.IFS(L4="Exceeds", "Top Performer", L4="Fully Meets", "Solid Performer", L4="Needs Improvement", "Underperformer", L4="PIP", "At Risk")} -> Solid Performer | D4: {=_xlfn.IFS(G4="Active", "Retained", G4="Voluntarily Terminated", "Voluntary Exit", G4="Terminated for Cause", "Involuntary Exit")} -> Voluntary Exit | E4: 41176 | F4: hours | G4: Voluntarily Terminated | H4: Production | I4: Kissy Sullivan | J4: 20 | K4: LinkedIn | L4: Fully Meets | M4: 3.02 | N4: 3
A5: 10088 | B5: MID | C5: {=_xlfn.IFS(L5="Exceeds", "Top Performer", L5="Fully Meets", "Solid Performer", L5="Needs Improvement", "Underperformer", L5="PIP", "At Risk")} -> Solid Performer | D5: {=_xlfn.IFS(G5="Active", "Retained", G5="Voluntarily Terminated", "Voluntary Exit", G5="Terminated for Cause", "Involuntary Exit")} -> Retained | F5: N/A-StillEmployed | G5: Active | H5: Production | I5: Elijiah Gray | J5: 16 | K5: Indeed | L5: Fully Meets | M5: 4.84 | N5: 5
A6: 10069 | B6: MID | C6: {=_xlfn.IFS(L6="Exceeds", "Top Performer", L6="Fully Meets", "Solid Performer", L6="Needs Improvement", "Underperformer", L6="PIP", "At Risk")} -> Solid Performer | D6: {=_xlfn.IFS(G6="Active", "Retained", G6="Voluntarily Terminated", "Voluntary Exit", G6="Terminated for Cause", "Involuntary Exit")} -> Voluntary Exit | E6: 42619 | F6: return to school | G6: Voluntarily Terminated | H6: Production | I6: Webster Butler | J6: 39 | K6: Google Search | L6: Fully Meets | M6: 5 | N6: 4
A7: 10002 | B7: MID | C7: {=_xlfn.IFS(L7="Exceeds", "Top Performer", L7="Fully Meets", "Solid Performer", L7="Needs Improvement", "Underperformer", L7="PIP", "At Risk")} -> Top Performer | D7: {=_xlfn.IFS(G7="Active", "Retained", G7="Voluntarily Terminated", "Voluntary Exit", G7="Terminated for Cause", "Involuntary Exit")} -> Retained | F7: N/A-StillEmployed | G7: Active | H7: Production | I7: Amy Dunn | J7: 11 | K7: LinkedIn | L7: Exceeds | M7: 5 | N7: 5
A8: 10194 | B8: HIGH | C8: {=_xlfn.IFS(L8="Exceeds", "Top Performer", L8="Fully Meets", "Solid Performer", L8="Needs Improvement", "Underperformer", L8="PIP", "At Risk")} -> Solid Performer | D8: {=_xlfn.IFS(G8="Active", "Retained", G8="Voluntarily Terminated", "Voluntary Exit", G8="Terminated for Cause", "Involuntary Exit")} -> Retained | F8: N/A-StillEmployed | G8: Active | H8: Software Engineering | I8: Alex Sweetwater | J8: 10 | K8: LinkedIn | L8: Fully Meets | M8: 3.04 | N8: 3
A9: 10062 | B9: MID | C9: {=_xlfn.IFS(L9="Exceeds", "Top Performer", L9="Fully Meets", "Solid Performer", L9="Needs Improvement", "Underperformer", L9="PIP", "At Risk")} -> Solid Performer | D9: {=_xlfn.IFS(G9="Active", "Retained", G9="Voluntarily Terminated", "Voluntary Exit", G9="Terminated for Cause", "Involuntary Exit")} -> Retained | F9: N/A-StillEmployed | G9: Active | H9: Production | I9: Ketsia Liebig | J9: 19 | K9: Employee Referral | L9: Fully Meets | M9: 5 | N9: 4
A10: 10114 | B10: MID | C10: {=_xlfn.IFS(L10="Exceeds", "Top Performer", L10="Fully Meets", "Solid Performer", L10="Needs Improvement", "Underperformer", L10="PIP", "At Risk")} -> Solid Performer | D10: {=_xlfn.IFS(G10="Active", "Retained", G10="Voluntarily Terminated", "Voluntary Exit", G10="Terminated for Cause", "Involuntary Exit")} -> Retained | F10: N/A-StillEmployed | G10: Active | H10: Production | I10: Brannon Miller | J10: 12 | K10: Diversity Job Fair | L10: Fully Meets | M10: 4.46 | N10: 3
A11: 10250 | B11: MID | C11: {=_xlfn.IFS(L11="Exceeds", "Top Performer", L11="Fully Meets", "Solid Performer", L11="Needs Improvement", "Underperformer", L11="PIP", "At Risk")} -> Solid Performer | D11: {=_xlfn.IFS(G11="Active", "Retained", G11="Voluntarily Terminated", "Voluntary Exit", G11="Terminated for Cause", "Involuntary Exit")} -> Retained | F11: N/A-StillEmployed | G11: Active | H11: IT/IS | I11: Peter Monroe | J11: 7 | K11: Indeed | L11: Fully Meets | M11: 5 | N11: 5
A12: 10252 | B12: MID | C12: {=_xlfn.IFS(L12="Exceeds", "Top Performer", L12="Fully Meets", "Solid Performer", L12="Needs Improvement", "Underperformer", L12="PIP", "At Risk")} -> Solid Performer | D12: {=_xlfn.IFS(G12="Active", "Retained", G12="Voluntarily Terminated", "Voluntary Exit", G12="Terminated for Cause", "Involuntary Exit")} -> Voluntary Exit | E12: 42747 | F12: Another position | G12: Voluntarily Terminated | H12: Production | I12: David Stanley | J12: 14 | K12: Diversity Job Fair | L12: Fully Meets | M12: 4.2 | N12: 4
A13: 10242 | B13: MID | C13: {=_xlfn.IFS(L13="Exceeds", "Top Performer", L13="Fully Meets", "Solid Performer", L13="Needs Improvement", "Underperformer", L13="PIP", "At Risk")} -> Solid Performer | D13: {=_xlfn.IFS(G13="Active", "Retained", G13="Voluntarily Terminated", "Voluntary Exit", G13="Terminated for Cause", "Involuntary Exit")} -> Voluntary Exit | E13: 42632 | F13: unhappy | G13: Voluntarily Terminated | H13: Production | I13: Kissy Sullivan | J13: 20 | K13: Diversity Job Fair | L13: Fully Meets | M13: 4.2 | N13: 3
A14: 10012 | B14: HIGH | C14: {=_xlfn.IFS(L14="Exceeds", "Top Performer", L14="Fully Meets", "Solid Performer", L14="Needs Improvement", "Underperformer", L14="PIP", "At Risk")} -> Top Performer | D14: {=_xlfn.IFS(G14="Active", "Retained", G14="Voluntarily Terminated", "Voluntary Exit", G14="Terminated for Cause", "Involuntary Exit")} -> Retained | F14: N/A-StillEmployed | G14: Active | H14: IT/IS | I14: Simon Roup | J14: 4 | K14: Diversity Job Fair | L14: Exceeds | M14: 4.28 | N14: 4
A15: 10265 | B15: MID | C15: {=_xlfn.IFS(L15="Exceeds", "Top Performer", L15="Fully Meets", "Solid Performer", L15="Needs Improvement", "Underperformer", L15="PIP", "At Risk")} -> Solid Performer | D15: {=_xlfn.IFS(G15="Active", "Retained", G15="Voluntarily Terminated", "Voluntary Exit", G15="Terminated for Cause", "Involuntary Exit")} -> Retained | F15: N/A-StillEmployed | G15: Active | H15: Production | I15: Kelley Spirea | J15: 18 | K15: Google Search | L15: Fully Meets | M15: 4.6 | N15: 4
A16: 10066 | B16: MID | C16: {=_xlfn.IFS(L16="Exceeds", "Top Performer", L16="Fully Meets", "Solid Performer", L16="Needs Improvement", "Underperformer", L16="PIP", "At Risk")} -> Solid Performer | D16: {=_xlfn.IFS(G16="Active", "Retained", G16="Voluntarily Terminated", "Voluntary Exit", G16="Terminated for Cause", "Involuntary Exit")} -> Voluntary Exit | E16: 42831 | F16: Another position | G16: Voluntarily Terminated | H16: Production | I16: Michael Albert | J16: 22 | K16: On-line Web application | L16: Fully Meets | M16: 5 | N16: 5
A17: 10061 | B17: MID | C17: {=_xlfn.IFS(L17="Exceeds", "Top Performer", L17="Fully Meets", "Solid Performer", L17="Needs Improvement", "Underperformer", L17="PIP", "At Risk")} -> Solid Performer | D17: {=_xlfn.IFS(G17="Active", "Retained", G17="Voluntarily Terminated", "Voluntary Exit", G17="Terminated for Cause", "Involuntary Exit")} -> Involuntary Exit | E17: 42951 | F17: attendance | G17: Terminated for Cause | H17: Production | I17: Kelley Spirea | J17: 18 | K17: Google Search | L17: Fully Meets | M17: 5 | N17: 4
A18: 10023 | B18: HIGH | C18: {=_xlfn.IFS(L18="Exceeds", "Top Performer", L18="Fully Meets", "Solid Performer", L18="Needs Improvement", "Underperformer", L18="PIP", "At Risk")} -> Top Performer | D18: {=_xlfn.IFS(G18="Active", "Retained", G18="Voluntarily Terminated", "Voluntary Exit", G18="Terminated for Cause", "Involuntary Exit")} -> Retained | F18: N/A-StillEmployed | G18: Active | H18: Production | I18: Kelley Spirea | J18: 18 | K18: Employee Referral | L18: Exceeds | M18: 4.4 | N18: 3
A19: 10055 | B19: MID | C19: {=_xlfn.IFS(L19="Exceeds", "Top Performer", L19="Fully Meets", "Solid Performer", L19="Needs Improvement", "Underperformer", L19="PIP", "At Risk")} -> Solid Performer | D19: {=_xlfn.IFS(G19="Active", "Retained", G19="Voluntarily Terminated", "Voluntary Exit", G19="Terminated for Cause", "Involuntary Exit")} -> Retained | F19: N/A-StillEmployed | G19: Active | H19: Production | I19: Elijiah Gray | J19: 16 | K19: Google Search | L19: Fully Meets | M19: 5 | N19: 5
A20: 10245 | B20: Executive | C20: {=_xlfn.IFS(L20="Exceeds", "Top Performer", L20="Fully Meets", "Solid Performer", L20="Needs Improvement", "Underperformer", L20="PIP", "At Risk")} -> Solid Performer | D20: {=_xlfn.IFS(G20="Active", "Retained", G20="Voluntarily Terminated", "Voluntary Exit", G20="Terminated for Cause", "Involuntary Exit")} -> Involuntary Exit | E20: 42259 | F20: performance | G20: Terminated for Cause | H20: IT/IS | I20: Simon Roup | J20: 4 | K20: Google Search | L20: Fully Meets | M20: 4.5 | N20: 4
A21: 10277 | B21: MID | C21: {=_xlfn.IFS(L21="Exceeds", "Top Performer", L21="Fully Meets", "Solid Performer", L21="Needs Improvement", "Underperformer", L21="PIP", "At Risk")} -> Solid Performer | D21: {=_xlfn.IFS(G21="Active", "Retained", G21="Voluntarily Terminated", "Voluntary Exit", G21="Terminated for Cause", "Involuntary Exit")} -> Retained | F21: N/A-StillEmployed | G21: Active | H21: Production | I21: Webster Butler | K21: LinkedIn | L21: Fully Meets | M21: 4.2 | N21: 4
A22: 10046 | B22: MID | C22: {=_xlfn.IFS(L22="Exceeds", "Top Performer", L22="Fully Meets", "Solid Performer", L22="Needs Improvement", "Underperformer", L22="PIP", "At Risk")} -> Solid Performer | D22: {=_xlfn.IFS(G22="Active", "Retained", G22="Voluntarily Terminated", "Voluntary Exit", G22="Terminated for Cause", "Involuntary Exit")} -> Retained | F22: N/A-StillEmployed | G22: Active | H22: Production | I22: Amy Dunn | J22: 11 | K22: Google Search | L22: Fully Meets | M22: 5 | N22: 3
A23: 10226 | B23: MID | C23: {=_xlfn.IFS(L23="Exceeds", "Top Performer", L23="Fully Meets", "Solid Performer", L23="Needs Improvement", "Underperformer", L23="PIP", "At Risk")} -> Solid Performer | D23: {=_xlfn.IFS(G23="Active", "Retained", G23="Voluntarily Terminated", "Voluntary Exit", G23="Terminated for Cause", "Involuntary Exit")} -> Retained | F23: N/A-StillEmployed | G23: Active | H23: Production | I23: Ketsia Liebig | J23: 19 | K23: Indeed | L23: Fully Meets | M23: 4.2 | N23: 3
A24: 10003 | B24: MID | C24: {=_xlfn.IFS(L24="Exceeds", "Top Performer", L24="Fully Meets", "Solid Performer", L24="Needs Improvement", "Underperformer", L24="PIP", "At Risk")} -> Top Performer | D24: {=_xlfn.IFS(G24="Active", "Retained", G24="Voluntarily Terminated", "Voluntary Exit", G24="Terminated for Cause", "Involuntary Exit")} -> Retained | F24: N/A-StillEmployed | G24: Active | H24: Production | I24: Brannon Miller | J24: 12 | K24: Indeed | L24: Exceeds | M24: 5 | N24: 3
A25: 10294 | B25: MID | C25: {=_xlfn.IFS(L25="Exceeds", "Top Performer", L25="Fully Meets", "Solid Performer", L25="Needs Improvement", "Underperformer", L25="PIP", "At Risk")} -> Underperformer | D25: {=_xlfn.IFS(G25="Active", "Retained", G25="Voluntarily Terminated", "Voluntary Exit", G25="Terminated for Cause", "Involuntary Exit")} -> Retained | F25: N/A-StillEmployed | G25: Active | H25: Production | I25: Michael Albert | J25: 22 | K25: CareerBuilder | L25: Needs Improvement | M25: 2 | N25: 3
A26: 10267 | B26: MID | C26: {=_xlfn.IFS(L26="Exceeds", "Top Performer", L26="Fully Meets", "Solid Performer", L26="Needs Improvement", "Underperformer", L26="PIP", "At Risk")} -> Solid Performer | D26: {=_xlfn.IFS(G26="Active", "Retained", G26="Voluntarily Terminated", "Voluntary Exit", G26="Terminated for Cause", "Involuntary Exit")} -> Voluntary Exit | E26: 41733 | F26: career change | G26: Voluntarily Terminated | H26: Production | I26: Elijiah Gray | J26: 16 | K26: Google Search | L26: Fully Meets | M26: 4.8 | N26: 5
